<!--<mujoco model="Cable">-->
<!--  <extension>-->
<!--    <plugin plugin="mujoco.elasticity.cable"/>-->
<!--  </extension>-->
<!--  <option impratio="5"/>-->
<!--  <statistic center="0 0 .3" extent="1"/>-->

<!--  <compiler autolimits="true"/>-->

<!--  <size memory="200M"/>-->

<!--  <worldbody>-->
<!--    <body name="slider1" pos="-.3 0 0">-->
<!--      <geom type="box" size=".01 .01 .01"/>-->
<!--    </body>-->
<!--    <composite type="cable" curve="s" count="41 1 1" size="0.5" offset="-.3 0 0">-->
<!--      <plugin plugin="mujoco.elasticity.cable">-->
<!--        &lt;!&ndash;Units are in Pa (SI)&ndash;&gt;-->
<!--        <config key="twist" value="2e4"/>-->
<!--        <config key="bend" value="4e4"/>-->
<!--        <config key="vmax" value="0.05"/>-->
<!--      </plugin>-->
<!--      <joint kind="main" damping=".015"/>-->
<!--      <geom type="capsule" size="0.005" rgba=".8 .2 .1 1" condim="1"/>-->
<!--    </composite>-->
<!--&lt;!&ndash;    <body name="slider2" pos="0.2 0 0.00">&ndash;&gt;-->
<!--&lt;!&ndash;      <geom type="box" size=".01 .01 .01"/>&ndash;&gt;-->
<!--&lt;!&ndash;    </body>&ndash;&gt;-->
<!--  </worldbody>-->
<!--&lt;!&ndash;  <contact>&ndash;&gt;-->
<!--&lt;!&ndash;    <exclude body1="/unnamed_composite_0B_last" body2="slider2"/>&ndash;&gt;-->
<!--&lt;!&ndash;  </contact>&ndash;&gt;-->
<!--&lt;!&ndash;  <equality>&ndash;&gt;-->
<!--&lt;!&ndash;    <connect name="right_boundary" body1="/unnamed_composite_0B_last" body2="slider2" anchor="0 0 0"/>&ndash;&gt;-->
<!--&lt;!&ndash;&lt;!&ndash;    <connect name="left_boundary" body1="B_first" body2="slider1" anchor="0 0 0"/>&ndash;&gt;&ndash;&gt;-->
<!--&lt;!&ndash;  </equality>&ndash;&gt;-->

<!--</mujoco>-->
<mujoco model="Cable">
  <compiler angle="radian"/>
  <option impratio="5" gravity="0 0 0">
  </option>
<!--  <option noslip_iterations="3">-->
<!--    <flag multiccd="enable"/>-->
<!--  </option>-->
  <size memory="200M"/>
  <statistic extent="1" center="0 0 0.3"/>
  <extension>
    <plugin plugin="mujoco.elasticity.cable">
      <instance name="composite">
        <config key="twist" value="2e4"/>
        <config key="bend" value="4e4"/>
        <config key="vmax" value="0.1"/>
      </instance>
    </plugin>
  </extension>
  <custom>
    <text name="composite_" data="rope_"/>
  </custom>
  <worldbody>
    <body name="slider1" pos="-0.3 0 0.3">
      <geom size="0.03 0.01 0.01" type="box" condim="3"/>
      <geom size="0.009 0.01 0.01" type="box" condim="3" pos="0.021 0.02 0"/>
      <geom size="0.009 0.01 0.01" type="box" condim="3" pos="-0.021 0.02 0"/>
      <geom size="0.009 0.01 0.01" type="box" condim="3" pos="0.021 -0.02 0"/>
      <geom size="0.009 0.01 0.01" type="box" condim="3" pos="-0.021 -0.02 0"/>
    </body>
    <body name="B_first" pos="-0.3 0 0.3">
      <joint name="J_first" pos="0 0 0" type="ball" group="3" damping="0.015"/>
      <geom name="G0" size="0.005 0.00625" pos="0.00625 0 0" quat="0.707107 0 -0.707107 0" type="capsule" condim="1" rgba="0 0.705783 1 1"/>
      <site name="S_first" pos="0 0 0" group="3"/>
      <plugin instance="composite"/>
      <body name="B_1" pos="0.0125 0 0">
        <joint name="J_1" pos="0 0 0" type="ball" group="3" damping="0.015"/>
        <geom name="G1" size="0.005 0.00625" pos="0.00625 0 0" quat="0.707107 0 -0.707107 0" type="capsule" condim="1" rgba="0 0.655989 1 1"/>
        <plugin instance="composite"/>
        <body name="B_2" pos="0.0125 0 0">
          <joint name="J_2" pos="0 0 0" type="ball" group="3" damping="0.015"/>
          <geom name="G2" size="0.005 0.00625" pos="0.00625 0 0" quat="0.707107 0 -0.707107 0" type="capsule" condim="1" rgba="0 0.512368 1 1"/>
          <plugin instance="composite"/>
          <body name="B_3" pos="0.0125 0 0">
            <joint name="J_3" pos="0 0 0" type="ball" group="3" damping="0.015"/>
            <geom name="G3" size="0.005 0.00625" pos="0.00625 0 0" quat="0.707107 0 -0.707107 0" type="capsule" condim="1" rgba="0 0.354071 1 1"/>
            <plugin instance="composite"/>
            <body name="B_4" pos="0.0125 0 0">
              <joint name="J_4" pos="0 0 0" type="ball" group="3" damping="0.015"/>
              <geom name="G4" size="0.005 0.00625" pos="0.00625 0 0" quat="0.707107 0 -0.707107 0" type="capsule" condim="1" rgba="0 0.247016 1 1"/>
              <plugin instance="composite"/>
              <body name="B_5" pos="0.0125 0 0">
                <joint name="J_5" pos="0 0 0" type="ball" group="3" damping="0.015"/>
                <geom name="G5" size="0.005 0.00625" pos="0.00625 0 0" quat="0.707107 0 -0.707107 0" type="capsule" condim="1" rgba="0 0.177048 1 1"/>
                <plugin instance="composite"/>
                <body name="B_6" pos="0.0125 0 0">
                  <joint name="J_6" pos="0 0 0" type="ball" group="3" damping="0.015"/>
                  <geom name="G6" size="0.005 0.00625" pos="0.00625 0 0" quat="0.707107 0 -0.707107 0" type="capsule" condim="1" rgba="0 0.132466 1 1"/>
                  <plugin instance="composite"/>
                  <body name="B_7" pos="0.0125 0 0">
                    <joint name="J_7" pos="0 0 0" type="ball" group="3" damping="0.015"/>
                    <geom name="G7" size="0.005 0.00625" pos="0.00625 0 0" quat="0.707107 0 -0.707107 0" type="capsule" condim="1" rgba="0 0.10475 1 1"/>
                    <plugin instance="composite"/>
                    <body name="B_8" pos="0.0125 0 0">
                      <joint name="J_8" pos="0 0 0" type="ball" group="3" damping="0.015"/>
                      <geom name="G8" size="0.005 0.00625" pos="0.00625 0 0" quat="0.707107 0 -0.707107 0" type="capsule" condim="1" rgba="0 0.0880006 1 1"/>
                      <plugin instance="composite"/>
                      <body name="B_9" pos="0.0125 0 0">
                        <joint name="J_9" pos="0 0 0" type="ball" group="3" damping="0.015"/>
                        <geom name="G9" size="0.005 0.00625" pos="0.00625 0 0" quat="0.707107 0 -0.707107 0" type="capsule" condim="1" rgba="0 0.0782314 1 1"/>
                        <plugin instance="composite"/>
                        <body name="B_10" pos="0.0125 0 0">
                          <joint name="J_10" pos="0 0 0" type="ball" group="3" damping="0.015"/>
                          <geom name="G10" size="0.005 0.00625" pos="0.00625 0 0" quat="0.707107 0 -0.707107 0" type="capsule" condim="1" rgba="0 0.0727861 1 1"/>
                          <plugin instance="composite"/>
                          <body name="B_11" pos="0.0125 0 0">
                            <joint name="J_11" pos="0 0 0" type="ball" group="3" damping="0.015"/>
                            <geom name="G11" size="0.005 0.00625" pos="0.00625 0 0" quat="0.707107 0 -0.707107 0" type="capsule" condim="1" rgba="0 0.0699149 1 1"/>
                            <plugin instance="composite"/>
                            <body name="B_12" pos="0.0125 0 0">
                              <joint name="J_12" pos="0 0 0" type="ball" group="3" damping="0.015"/>
                              <geom name="G12" size="0.005 0.00624999" pos="0.00624999 0 0" quat="0.707107 0 -0.707107 0" type="capsule" condim="1" rgba="0 0.0684785 1 1"/>
                              <plugin instance="composite"/>
                              <body name="B_13" pos="0.0125 0 0">
                                <joint name="J_13" pos="0 0 0" type="ball" group="3" damping="0.015"/>
                                <geom name="G13" size="0.005 0.00625" pos="0.00625 0 0" quat="0.707107 0 -0.707107 0" type="capsule" condim="1" rgba="0 0.0677457 1 1"/>
                                <plugin instance="composite"/>
                                <body name="B_14" pos="0.0125 0 0">
                                  <joint name="J_14" pos="0 0 0" type="ball" group="3" damping="0.015"/>
                                  <geom name="G14" size="0.005 0.00625" pos="0.00625 0 0" quat="0.707107 0 -0.707107 0" type="capsule" condim="1" rgba="0 0.0672557 1 1"/>
                                  <plugin instance="composite"/>
                                  <body name="B_15" pos="0.0125 0 0">
                                    <joint name="J_15" pos="0 0 0" type="ball" group="3" damping="0.015"/>
                                    <geom name="G15" size="0.005 0.00625" pos="0.00625 0 0" quat="0.707107 0 -0.707107 0" type="capsule" condim="1" rgba="0 0.0667259 1 1"/>
                                    <plugin instance="composite"/>
                                    <body name="B_16" pos="0.0125 0 0">
                                      <joint name="J_16" pos="0 0 0" type="ball" group="3" damping="0.015"/>
                                      <geom name="G16" size="0.005 0.00625" pos="0.00625 0 0" quat="0.707107 0 -0.707107 0" type="capsule" condim="1" rgba="0 0.0659899 1 1"/>
                                      <plugin instance="composite"/>
                                      <body name="B_17" pos="0.0125 0 0">
                                        <joint name="J_17" pos="0 0 0" type="ball" group="3" damping="0.015"/>
                                        <geom name="G17" size="0.005 0.00624999" pos="0.00624999 0 0" quat="0.707107 0 -0.707107 0" type="capsule" condim="1" rgba="0 0.0649561 1 1"/>
                                        <plugin instance="composite"/>
                                        <body name="B_18" pos="0.0125 0 0">
                                          <joint name="J_18" pos="0 0 0" type="ball" group="3" damping="0.015"/>
                                          <geom name="G18" size="0.005 0.00625" pos="0.00625 0 0" quat="0.707107 0 -0.707107 0" type="capsule" condim="1" rgba="0 0.0635808 1 1"/>
                                          <plugin instance="composite"/>
                                          <body name="B_19" pos="0.0125 0 0">
                                            <joint name="J_19" pos="0 0 0" type="ball" group="3" damping="0.015"/>
                                            <geom name="G19" size="0.005 0.00625" pos="0.00625 0 0" quat="0.707107 0 -0.707107 0" type="capsule" condim="1" rgba="0 0.0618502 1 1"/>
                                            <plugin instance="composite"/>
                                            <body name="B_20" pos="0.0125 0 0">
                                              <joint name="J_20" pos="0 0 0" type="ball" group="3" damping="0.015"/>
                                              <geom name="G20" size="0.005 0.00624999" pos="0.00624999 0 0" quat="0.707107 0 -0.707107 0" type="capsule" condim="1" rgba="0 0.0597683 1 1"/>
                                              <plugin instance="composite"/>
                                              <body name="B_21" pos="0.0125 0 0">
                                                <joint name="J_21" pos="0 0 0" type="ball" group="3" damping="0.015"/>
                                                <geom name="G21" size="0.005 0.00625001" pos="0.00625001 0 0" quat="0.707107 0 -0.707107 0" type="capsule" condim="1" rgba="0 0.0573504 1 1"/>
                                                <plugin instance="composite"/>
                                                <body name="B_22" pos="0.0125 0 0">
                                                  <joint name="J_22" pos="0 0 0" type="ball" group="3" damping="0.015"/>
                                                  <geom name="G22" size="0.005 0.00624999" pos="0.00624999 0 0" quat="0.707107 0 -0.707107 0" type="capsule" condim="1" rgba="0 0.0546176 1 1"/>
                                                  <plugin instance="composite"/>
                                                  <body name="B_23" pos="0.0125 0 0">
                                                    <joint name="J_23" pos="0 0 0" type="ball" group="3" damping="0.015"/>
                                                    <geom name="G23" size="0.005 0.00625001" pos="0.00625001 0 0" quat="0.707107 0 -0.707107 0" type="capsule" condim="1" rgba="0 0.0515946 1 1"/>
                                                    <plugin instance="composite"/>
                                                    <body name="B_24" pos="0.0125 0 0">
                                                      <joint name="J_24" pos="0 0 0" type="ball" group="3" damping="0.015"/>
                                                      <geom name="G24" size="0.005 0.00624999" pos="0.00624999 0 0" quat="0.707107 0 -0.707107 0" type="capsule" condim="1" rgba="0 0.0483087 1 1"/>
                                                      <plugin instance="composite"/>
                                                      <body name="B_25" pos="0.0125 0 0">
                                                        <joint name="J_25" pos="0 0 0" type="ball" group="3" damping="0.015"/>
                                                        <geom name="G25" size="0.005 0.00624999" pos="0.00624999 0 0" quat="0.707107 0 -0.707107 0" type="capsule" condim="1" rgba="0 0.0447891 1 1"/>
                                                        <plugin instance="composite"/>
                                                        <body name="B_26" pos="0.0125 0 0">
                                                          <joint name="J_26" pos="0 0 0" type="ball" group="3" damping="0.015"/>
                                                          <geom name="G26" size="0.005 0.00625001" pos="0.00625001 0 0" quat="0.707107 0 -0.707107 0" type="capsule" condim="1" rgba="0 0.0410685 1 1"/>
                                                          <plugin instance="composite"/>
                                                          <body name="B_27" pos="0.0125 0 0">
                                                            <joint name="J_27" pos="0 0 0" type="ball" group="3" damping="0.015"/>
                                                            <geom name="G27" size="0.005 0.00624999" pos="0.00624999 0 0" quat="0.707107 0 -0.707107 0" type="capsule" condim="1" rgba="0 0.0371831 1 1"/>
                                                            <plugin instance="composite"/>
                                                            <body name="B_28" pos="0.0125 0 0">
                                                              <joint name="J_28" pos="0 0 0" type="ball" group="3" damping="0.015"/>
                                                              <geom name="G28" size="0.005 0.00625001" pos="0.00625001 0 0" quat="0.707107 0 -0.707107 0" type="capsule" condim="1" rgba="0 0.033175 1 1"/>
                                                              <plugin instance="composite"/>
                                                              <body name="B_29" pos="0.0125 0 0">
                                                                <joint name="J_29" pos="0 0 0" type="ball" group="3" damping="0.015"/>
                                                                <geom name="G29" size="0.005 0.00624999" pos="0.00624999 0 0" quat="0.707107 0 -0.707107 0" type="capsule" condim="1" rgba="0 0.0290933 1 1"/>
                                                                <plugin instance="composite"/>
                                                                <body name="B_30" pos="0.0125 0 0">
                                                                  <joint name="J_30" pos="0 0 0" type="ball" group="3" damping="0.015"/>
                                                                  <geom name="G30" size="0.005 0.00624999" pos="0.00624999 0 0" quat="0.707107 0 -0.707107 0" type="capsule" condim="1" rgba="0 0.024995 1 1"/>
                                                                  <plugin instance="composite"/>
                                                                  <body name="B_31" pos="0.0125 0 0">
                                                                    <joint name="J_31" pos="0 0 0" type="ball" group="3" damping="0.015"/>
                                                                    <geom name="G31" size="0.005 0.00625001" pos="0.00625001 0 0" quat="0.707107 0 -0.707107 0" type="capsule" condim="1" rgba="0 0.0209467 1 1"/>
                                                                    <plugin instance="composite"/>
                                                                    <body name="B_32" pos="0.0125 0 0">
                                                                      <joint name="J_32" pos="0 0 0" type="ball" group="3" damping="0.015"/>
                                                                      <geom name="G32" size="0.005 0.00624999" pos="0.00624999 0 0" quat="0.707107 0 -0.707107 0" type="capsule" condim="1" rgba="0 0.0170235 1 1"/>
                                                                      <plugin instance="composite"/>
                                                                      <body name="B_33" pos="0.0125 0 0">
                                                                        <joint name="J_33" pos="0 0 0" type="ball" group="3" damping="0.015"/>
                                                                        <geom name="G33" size="0.005 0.00625001" pos="0.00625001 0 0" quat="0.707107 0 -0.707107 0" type="capsule" condim="1" rgba="0 0.0133084 1 1"/>
                                                                        <plugin instance="composite"/>
                                                                        <body name="B_34" pos="0.0125 0 0">
                                                                          <joint name="J_34" pos="0 0 0" type="ball" group="3" damping="0.015"/>
                                                                          <geom name="G34" size="0.005 0.00624999" pos="0.00624999 0 0" quat="0.707107 0 -0.707107 0" type="capsule" condim="1" rgba="0 0.00988954 1 1"/>
                                                                          <plugin instance="composite"/>
                                                                          <body name="B_35" pos="0.0125 0 0">
                                                                            <joint name="J_35" pos="0 0 0" type="ball" group="3" damping="0.015"/>
                                                                            <geom name="G35" size="0.005 0.00624999" pos="0.00624999 0 0" quat="0.707107 0 -0.707107 0" type="capsule" condim="1" rgba="0 0.00685654 1 1"/>
                                                                            <plugin instance="composite"/>
                                                                            <body name="B_36" pos="0.0125 0 0">
                                                                              <joint name="J_36" pos="0 0 0" type="ball" group="3" damping="0.015"/>
                                                                              <geom name="G36" size="0.005 0.00625001" pos="0.00625001 0 0" quat="0.707107 0 -0.707107 0" type="capsule" condim="1" rgba="0 0.00429628 1 1"/>
                                                                              <plugin instance="composite"/>
                                                                              <body name="B_37" pos="0.0125 0 0">
                                                                                <joint name="J_37" pos="0 0 0" type="ball" group="3" damping="0.015"/>
                                                                                <geom name="G37" size="0.005 0.00624999" pos="0.00624999 0 0" quat="0.707107 0 -0.707107 0" type="capsule" condim="1" rgba="0 0.00228791 1 1"/>
                                                                                <plugin instance="composite"/>
                                                                                <body name="B_38" pos="0.0125 0 0">
                                                                                  <joint name="J_38" pos="0 0 0" type="ball" group="3" damping="0.015"/>
                                                                                  <geom name="G38" size="0.005 0.00625001" pos="0.00625001 0 0" quat="0.707107 0 -0.707107 0" type="capsule" condim="1" rgba="0 0.000898957 1 1"/>
                                                                                  <plugin instance="composite"/>
                                                                                  <body name="B_last" pos="0.0125 0 0">
                                                                                    <joint name="J_last" pos="0 0 0" type="ball" group="3" damping="0.015"/>
                                                                                    <geom name="G39" size="0.005 0.00624999" pos="0.00624999 0 0" quat="0.707107 0 -0.707107 0" type="capsule" condim="1" rgba="0 0.000366955 1 1"/>
                                                                                    <site name="S_last" pos="0.0125 0 0" group="3"/>
                                                                                    <plugin instance="composite"/>
                                                                                    <body name="slider2" pos="0.01 0 0">
                                                                                      <geom size="0.03 0.01 0.01" type="box" condim="3"/>
                                                                                      <geom size="0.009 0.01 0.01" type="box" condim="3" pos="0.021 0.02 0"/>
                                                                                      <geom size="0.009 0.01 0.01" type="box" condim="3" pos="-0.021 0.02 0"/>
                                                                                      <geom size="0.009 0.01 0.01" type="box" condim="3" pos="0.021 -0.02 0"/>
                                                                                      <geom size="0.009 0.01 0.01" type="box" condim="3" pos="-0.021 -0.02 0"/>
                                                                                    </body>
                                                                                  </body>
                                                                                </body>
                                                                              </body>
                                                                            </body>
                                                                          </body>
                                                                        </body>
                                                                      </body>
                                                                    </body>
                                                                  </body>
                                                                </body>
                                                              </body>
                                                            </body>
                                                          </body>
                                                        </body>
                                                      </body>
                                                    </body>
                                                  </body>
                                                </body>
                                              </body>
                                            </body>
                                          </body>
                                        </body>
                                      </body>
                                    </body>
                                  </body>
                                </body>
                              </body>
                            </body>
                          </body>
                        </body>
                      </body>
                    </body>
                  </body>
                </body>
              </body>
            </body>
          </body>
        </body>
      </body>
    </body>
  </worldbody>
  <contact>
    <exclude body1="B_first" body2="slider1"/>
    <exclude body1="B_first" body2="B_1"/>
    <exclude body1="B_1" body2="B_2"/>
    <exclude body1="B_2" body2="B_3"/>
    <exclude body1="B_3" body2="B_4"/>
    <exclude body1="B_4" body2="B_5"/>
    <exclude body1="B_5" body2="B_6"/>
    <exclude body1="B_6" body2="B_7"/>
    <exclude body1="B_7" body2="B_8"/>
    <exclude body1="B_8" body2="B_9"/>
    <exclude body1="B_9" body2="B_10"/>
    <exclude body1="B_10" body2="B_11"/>
    <exclude body1="B_11" body2="B_12"/>
    <exclude body1="B_12" body2="B_13"/>
    <exclude body1="B_13" body2="B_14"/>
    <exclude body1="B_14" body2="B_15"/>
    <exclude body1="B_15" body2="B_16"/>
    <exclude body1="B_16" body2="B_17"/>
    <exclude body1="B_17" body2="B_18"/>
    <exclude body1="B_18" body2="B_19"/>
    <exclude body1="B_19" body2="B_20"/>
    <exclude body1="B_20" body2="B_21"/>
    <exclude body1="B_21" body2="B_22"/>
    <exclude body1="B_22" body2="B_23"/>
    <exclude body1="B_23" body2="B_24"/>
    <exclude body1="B_24" body2="B_25"/>
    <exclude body1="B_25" body2="B_26"/>
    <exclude body1="B_26" body2="B_27"/>
    <exclude body1="B_27" body2="B_28"/>
    <exclude body1="B_28" body2="B_29"/>
    <exclude body1="B_29" body2="B_30"/>
    <exclude body1="B_30" body2="B_31"/>
    <exclude body1="B_31" body2="B_32"/>
    <exclude body1="B_32" body2="B_33"/>
    <exclude body1="B_33" body2="B_34"/>
    <exclude body1="B_34" body2="B_35"/>
    <exclude body1="B_35" body2="B_36"/>
    <exclude body1="B_36" body2="B_37"/>
    <exclude body1="B_37" body2="B_38"/>
    <exclude body1="B_38" body2="B_last"/>
    <exclude body1="B_last" body2="slider2"/>
  </contact>
</mujoco>
